Workbook

Sheet Resumen
A1: Balance de cartografía · Contrato 149-2024 (Consorcio Aero-Bat Antioquia) · cortes dic-2024, dic-2025 y jun-2026
A2: Fuente: informes de avance N°8, N°20 y N°26 de Valor+ (Contrato 24MA176H1682). Hectáreas equivalentes = área × % de productos entregados. Azul = dato transcrito del informe; negro = fórmula. Datos al 5-oct-2026: el más reciente tiene ~3 meses de antigüedad.
A3: Nota metodológica: se conserva el cálculo original de 2025 como rango matemático. No se retrotrae automáticamente el estado de vuelo incompleto de jun-26 a dic-25.
A4: SUPUESTOS (editables)
A5: Peso de cada producto en el % de avance (contrato: Ortofoto 45%, MDT 45%, GDB 10%; Tabla 26 informe dic-2025 p.64)
A6: Ortofoto | C6: 0.45 | D6: Pesos contractuales
A7: MDT (modelo digital del terreno) | C7: 0.45 | D7: Ídem
A8: Vectorial (GDB) · corte 2024 | C8: 0 | D8: Criterio del libro ejemplo: la interventoría no sumó GDB urbanas en dic-2024
A9: Vectorial (GDB) · cortes 2025 y 2026 | C9: 0.1 | D9: Los informes 2025-26 sí cuentan GDB (ver contraste #1)
A11: CARTOGRAFÍA RURAL | B11: Fuente / nota | C11: Dic-2024 | D11: Dic-2025 | E11: Jun-2026
A12: Municipios en el alcance vigente | B12: 57 rurales originales + 8 de Fase II desde may-2025 | C12: =COUNTA(Rural_2024!B5:B61) -> 57 | D12: =COUNTA(Rural_2025!B5:B69) -> 65 | E12: =COUNTA(Rural_2026!B5:B69) -> 65
A13: Municipios con entregas verificadas por municipio | B13: Con evidencia municipal de ≥1 producto entregado | C13: =COUNTIF(Rural_2024!T5:T61,"Con entregas") -> 15 | D13: =COUNTIF(Rural_2025!V5:V69,"Con entregas verificadas") -> 15 | E13: =COUNTIF(Rural_2026!V5:V69,"Con entregas verificadas") -> 30
A14: Municipios sin evidencia municipal de entregas | B14: El informe no dice por municipio si entregó (amarillo en hojas) | C14: 0 | D14: =COUNTIF(Rural_2025!V5:V69,"Sin evidencia municipal") -> 50 | E14: =COUNTIF(Rural_2026!V5:V69,"Sin evidencia municipal") -> 25
A15: Área base de cálculo (ha) | B15: Área contrato; en 2024 área de la interventoría donde la reporta | C15: =Rural_2024!H62 -> 3489900 | D15: =Rural_2025!H70 -> 4393721.1 | E15: =Rural_2026!H70 -> 4393721.1
A16: HA EQUIVALENTES PONDERADAS · mínimo/inferencia | B16: Cálculo ponderado; 2025-26: rango por falta de desagregación municipal | C16: =Rural_2024!O62 -> 545704.07 | D16: =Rural_2025!O70 -> 1766327.7 | E16: =Rural_2026!O70 -> 2601829.9
A17: HA EQUIVALENTES PONDERADAS · máximo/inferencia | B17: Escenario matemático, no avance territorial acreditado | C17: =Rural_2024!O62 -> 545704.07 | D17: =Rural_2025!P70 -> 3663421.2 | E17: =Rural_2026!P70 -> 2832207.3
A18: % de avance en hectáreas · mínimo | B18: Ha eq. mínimo / área base | C18: =Rural_2024!N62 -> 0.15636668 | D18: =Rural_2025!M70 -> 0.4020118 | E18: =Rural_2026!M70 -> 0.59217002
A19: % de avance en hectáreas · máximo | B19: Ha eq. máximo / área base | C19: =Rural_2024!N62 -> 0.15636668 | D19: =Rural_2025!N70 -> 0.83378555 | E19: =Rural_2026!N70 -> 0.64460334
A20: % de avance que reporta el informe | B20: 2024: ponderado por hectárea (importancia); 2025-26: conteo simple de productos | C20: 0.1564 | D20: 0.631 | E20: 0.815
A21: Productos entregados (ortofoto+MDT+GDB) · reportado | B21: Tabla resumen del informe | C21: 25 | D21: 123 | E21: 159
A22: Productos contratados en el sector | B22: Rural 2024: 57×3; 2025-26: 65×3 = 195 (Tabla 30/29) | C22: =57*3 -> 171 | D22: 195 | E22: 195
A23: % por conteo simple = entregados / contratados | B23: Reproduce el % del informe en 2025-26 → cambió la metodología | C23: =C21/C22 -> 0.14619883 | D23: =D21/D22 -> 0.63076923 | E23: =E21/E22 -> 0.81538462
A24: Diferencia: % por conteo − % en hectáreas máximo | B24: Cuánto "infla" el conteo frente a las hectáreas | C24: =C23-C19 -> -0.010167848 | D24: =D23-D19 -> -0.20301632 | E24: =E23-E19 -> 0.17078128
A25: Ortofotos entregadas (reportado) | B25: Tabla resumen del informe | C25: 12 | D25: 49 | E25: 54
A26: MDT entregados (reportado) | B26: Tabla resumen del informe | C26: 13 | D26: 47 | E26: 54
A27: GDB entregadas (reportado) | B27: Tabla resumen del informe | C27: 0 | D27: 27 | E27: 51
A28: Ortofotos aprobadas por interventoría | B28: Tabla resumen / texto del informe | C28: 10 | D28: 44 | E28: 52
A29: MDT aprobados por interventoría | B29: Tabla resumen / texto del informe | C29: 9 | D29: 44 | E29: 52
A30: GDB aprobadas por interventoría | B30: Tabla resumen / texto del informe | C30: 0 | D30: 17 | E30: 44
A31: Ortofotos con marca municipal evidenciada | B31: Suma de marcas en las hojas; si < reportado, la diferencia no está desagregada | C31: =Rural_2024!I62 -> 12 | D31: =Rural_2025!I70 -> 14 | E31: =Rural_2026!I70 -> 27
A32: MDT con marca municipal evidenciada | B32: Suma de marcas en las hojas; si < reportado, la diferencia no está desagregada | C32: =Rural_2024!J62 -> 13 | D32: =Rural_2025!J70 -> 14 | E32: =Rural_2026!J70 -> 26
A33: GDB con marca municipal evidenciada | B33: Suma de marcas en las hojas; si < reportado, la diferencia no está desagregada | C33: =Rural_2024!K62 -> 0 | D33: =Rural_2025!K70 -> 11 | E33: =Rural_2026!K70 -> 25
A34: Ha equivalentes CONFORMES (aprobadas por interventoría, solo 2024) | B34: Tabla 25 col. "% conforme" | C34: =Rural_2024!R62 -> 494844.21
A35: Ha equivalentes OFICIALES ante el IGAC | B35: Productos con estado "Oficial" (Tabla 40 p.80); dic-2025: solo 4 productos conformes, sin detalle municipal | C35: 0 | D35: =Rural_2025!U70 -> 0 | E35: =Rural_2026!U70 -> 339479.9
A36: % oficial IGAC sobre el área base | B36: Hectáreas equivalentes oficiales / área base | C36: 0 | D36: =D35/Rural_2025!H70 -> 0 | E36: =E35/Rural_2026!H70 -> 0.077264781
A37: Productos rurales radicados/en poder del IGAC (reportado) | B37: Dic-25: Tabla 31 (35, pero filas suman 36); jun-26: Tabla 39 p.79 (78 = 49 devueltos + 11 en revisión + 18 oficiales) | C37: 0 | D37: 35 | E37: 78
A39: CARTOGRAFÍA URBANA | B39: Fuente / nota | C39: Dic-2024 | D39: Dic-2025 | E39: Jun-2026
A40: Municipios en el alcance vigente | B40: 49 municipios | C40: =COUNTA(Urbano_2024!B5:B53) -> 49 | D40: =COUNTA(Urbano_2025!B5:B53) -> 49 | E40: =COUNTA(Urbano_2026!B5:B53) -> 49
A41: Municipios con entregas verificadas por municipio | B41: Con evidencia municipal de ≥1 producto entregado | C41: =COUNTIF(Urbano_2024!T5:T53,"Con entregas") -> 20 | D41: =COUNTIF(Urbano_2025!V5:V53,"Con entregas verificadas") -> 49 | E41: =COUNTIF(Urbano_2026!V5:V53,"Con entregas verificadas") -> 49
A42: Municipios sin evidencia municipal de entregas | B42: El informe no dice por municipio si entregó (amarillo en hojas) | C42: 0 | D42: =COUNTIF(Urbano_2025!V5:V53,"Sin evidencia municipal") -> 0 | E42: =COUNTIF(Urbano_2026!V5:V53,"Sin evidencia municipal") -> 0
...

Sheet Rural_2024
A1: Cartografía rural · corte 31-dic-2024
A2: Informe de avance N°8 (dic-2024), Valor+, Contrato 24MA176H1682. Área contrato: Tablas 2-3 págs. 8-9. Entregas, importancia y % conforme: Tabla 25 págs. 44-45 (rural) y Tabla 28 págs. 51-52 (urbano). Azul = dato transcrito; negro = fórmula.
A4: Cód. DANE | B4: Municipio | C4: Región | D4: Provincia | E4: Alcance | F4: Área contrato (ha) | G4: Área según interventoría (ha) | H4: Área base (ha) | I4: Ortofoto entregada (1/0) | J4: MDT entregado (1/0) | K4: Vectorial entregado (1/0) | L4: Importancia reportada (%) | M4: % conforme reportado | N4: % avance entregado | O4: Ha equivalentes entregadas | P4: Ha pendientes | Q4: % conforme del municipio | R4: Ha equivalentes conformes | S4: Área bruta con entregas (ha) | T4: Estado | U4: Avance ponderado contractual (45/45/10) | V4: Ha equivalentes ponderadas | W4: Cobertura territorial ≥1 producto | X4: Avance por conteo simple | Y4: Porcentaje reportado por informe | Z4: Diferencia reporte-cálculo | AA4: Observación
A5: 05197 | B5: Cocorná | C5: Oriente | D5: Provincia ABT | E5: Original | F5: 24405 | G5: 24404.89 | H5: =IF(G5="",F5,G5) -> 24404.89 | I5: 1 | J5: 1 | K5: 0 | L5: 0.007 | M5: 0.0063 | N5: =I5*Resumen!$C$6+J5*Resumen!$C$7+K5*Resumen!$C$8 -> 0.9 | O5: =H5*N5 -> 21964.401 | P5: =H5-O5 -> 2440.489 | Q5: =IF(L5>0,MIN(1,M5/L5,IF(K5=0,N5,1)),0) -> 0.9 | R5: =H5*Q5 -> 21964.401 | S5: =IF(N5>0,H5,0) -> 24404.89 | T5: =IF(N5>0,"Con entregas","Sin entregas") -> Con entregas | U5: =I5*Resumen!$C$6+J5*Resumen!$C$7+K5*Resumen!$C$9 -> 0.9 | V5: =H5*U5 -> 21964.401 | W5: =IF(COUNTIF(I5:K5,1)>0,1,0) -> 1 | X5: =COUNTIF(I5:K5,1)/3 -> 0.66666667 | Y5: =N5 -> 0.9 | Z5: =Y5-U5 -> 0 | AA5: El porcentaje reportado puede ser aporte al avance global; no necesariamente avance interno.
A6: 05206 | B6: Concepción | C6: Oriente | D6: Provincia ABT | E6: Original | F6: 20260 | H6: =IF(G6="",F6,G6) -> 20260 | I6: 0 | J6: 0 | K6: 0 | N6: =I6*Resumen!$C$6+J6*Resumen!$C$7+K6*Resumen!$C$8 -> 0 | O6: =H6*N6 -> 0 | P6: =H6-O6 -> 20260 | Q6: =IF(L6>0,MIN(1,M6/L6,IF(K6=0,N6,1)),0) -> 0 | R6: =H6*Q6 -> 0 | S6: =IF(N6>0,H6,0) -> 0 | T6: =IF(N6>0,"Con entregas","Sin entregas") -> Sin entregas | U6: =I6*Resumen!$C$6+J6*Resumen!$C$7+K6*Resumen!$C$9 -> 0 | V6: =H6*U6 -> 0 | W6: =IF(COUNTIF(I6:K6,1)>0,1,0) -> 0 | X6: =COUNTIF(I6:K6,1)/3 -> 0 | Y6: =N6 -> 0 | Z6: =Y6-U6 -> 0 | AA6: El porcentaje reportado puede ser aporte al avance global; no necesariamente avance interno.
A7: 05649 | B7: San Carlos | C7: Oriente | D7: Provincia ABT | E7: Original | F7: 72395 | G7: 72394.57 | H7: =IF(G7="",F7,G7) -> 72394.57 | I7: 1 | J7: 1 | K7: 0 | L7: 0.0207 | M7: 0.0187 | N7: =I7*Resumen!$C$6+J7*Resumen!$C$7+K7*Resumen!$C$8 -> 0.9 | O7: =H7*N7 -> 65155.113 | P7: =H7-O7 -> 7239.457 | Q7: =IF(L7>0,MIN(1,M7/L7,IF(K7=0,N7,1)),0) -> 0.9 | R7: =H7*Q7 -> 65155.113 | S7: =IF(N7>0,H7,0) -> 72394.57 | T7: =IF(N7>0,"Con entregas","Sin entregas") -> Con entregas | U7: =I7*Resumen!$C$6+J7*Resumen!$C$7+K7*Resumen!$C$9 -> 0.9 | V7: =H7*U7 -> 65155.113 | W7: =IF(COUNTIF(I7:K7,1)>0,1,0) -> 1 | X7: =COUNTIF(I7:K7,1)/3 -> 0.66666667 | Y7: =N7 -> 0.9 | Z7: =Y7-U7 -> 0 | AA7: El porcentaje reportado puede ser aporte al avance global; no necesariamente avance interno.
A8: 05652 | B8: San Francisco | C8: Oriente | D8: Provincia ABT | E8: Original | F8: 35717 | H8: =IF(G8="",F8,G8) -> 35717 | I8: 0 | J8: 0 | K8: 0 | N8: =I8*Resumen!$C$6+J8*Resumen!$C$7+K8*Resumen!$C$8 -> 0 | O8: =H8*N8 -> 0 | P8: =H8-O8 -> 35717 | Q8: =IF(L8>0,MIN(1,M8/L8,IF(K8=0,N8,1)),0) -> 0 | R8: =H8*Q8 -> 0 | S8: =IF(N8>0,H8,0) -> 0 | T8: =IF(N8>0,"Con entregas","Sin entregas") -> Sin entregas | U8: =I8*Resumen!$C$6+J8*Resumen!$C$7+K8*Resumen!$C$9 -> 0 | V8: =H8*U8 -> 0 | W8: =IF(COUNTIF(I8:K8,1)>0,1,0) -> 0 | X8: =COUNTIF(I8:K8,1)/3 -> 0 | Y8: =N8 -> 0 | Z8: =Y8-U8 -> 0 | AA8: El porcentaje reportado puede ser aporte al avance global; no necesariamente avance interno.
A9: 05310 | B9: Gómez Plata | C9: Norte | D9: Provincia Bio-Energética del Norte | E9: Original | F9: 33207 | H9: =IF(G9="",F9,G9) -> 33207 | I9: 0 | J9: 0 | K9: 0 | N9: =I9*Resumen!$C$6+J9*Resumen!$C$7+K9*Resumen!$C$8 -> 0 | O9: =H9*N9 -> 0 | P9: =H9-O9 -> 33207 | Q9: =IF(L9>0,MIN(1,M9/L9,IF(K9=0,N9,1)),0) -> 0 | R9: =H9*Q9 -> 0 | S9: =IF(N9>0,H9,0) -> 0 | T9: =IF(N9>0,"Con entregas","Sin entregas") -> Sin entregas | U9: =I9*Resumen!$C$6+J9*Resumen!$C$7+K9*Resumen!$C$9 -> 0 | V9: =H9*U9 -> 0 | W9: =IF(COUNTIF(I9:K9,1)>0,1,0) -> 0 | X9: =COUNTIF(I9:K9,1)/3 -> 0 | Y9: =N9 -> 0 | Z9: =Y9-U9 -> 0 | AA9: El porcentaje reportado puede ser aporte al avance global; no necesariamente avance interno.
A10: 05055 | B10: Argelia | C10: Oriente | D10: Provincia La Paz | E10: Original | F10: 24702 | H10: =IF(G10="",F10,G10) -> 24702 | I10: 0 | J10: 0 | K10: 0 | N10: =I10*Resumen!$C$6+J10*Resumen!$C$7+K10*Resumen!$C$8 -> 0 | O10: =H10*N10 -> 0 | P10: =H10-O10 -> 24702 | Q10: =IF(L10>0,MIN(1,M10/L10,IF(K10=0,N10,1)),0) -> 0 | R10: =H10*Q10 -> 0 | S10: =IF(N10>0,H10,0) -> 0 | T10: =IF(N10>0,"Con entregas","Sin entregas") -> Sin entregas | U10: =I10*Resumen!$C$6+J10*Resumen!$C$7+K10*Resumen!$C$9 -> 0 | V10: =H10*U10 -> 0 | W10: =IF(COUNTIF(I10:K10,1)>0,1,0) -> 0 | X10: =COUNTIF(I10:K10,1)/3 -> 0 | Y10: =N10 -> 0 | Z10: =Y10-U10 -> 0 | AA10: El porcentaje reportado puede ser aporte al avance global; no necesariamente avance interno.
A11: 05483 | B11: Nariño | C11: Oriente | D11: Provincia La Paz | E11: Original | F11: 31797 | H11: =IF(G11="",F11,G11) -> 31797 | I11: 0 | J11: 0 | K11: 0 | N11: =I11*Resumen!$C$6+J11*Resumen!$C$7+K11*Resumen!$C$8 -> 0 | O11: =H11*N11 -> 0 | P11: =H11-O11 -> 31797 | Q11: =IF(L11>0,MIN(1,M11/L11,IF(K11=0,N11,1)),0) -> 0 | R11: =H11*Q11 -> 0 | S11: =IF(N11>0,H11,0) -> 0 | T11: =IF(N11>0,"Con entregas","Sin entregas") -> Sin entregas | U11: =I11*Resumen!$C$6+J11*Resumen!$C$7+K11*Resumen!$C$9 -> 0 | V11: =H11*U11 -> 0 | W11: =IF(COUNTIF(I11:K11,1)>0,1,0) -> 0 | X11: =COUNTIF(I11:K11,1)/3 -> 0 | Y11: =N11 -> 0 | Z11: =Y11-U11 -> 0 | AA11: El porcentaje reportado puede ser aporte al avance global; no necesariamente avance interno.
A12: 05756 | B12: Sonsón | C12: Oriente | D12: Provincia La Paz | E12: Original | F12: 135439 | H12: =IF(G12="",F12,G12) -> 135439 | I12: 0 | J12: 0 | K12: 0 | N12: =I12*Resumen!$C$6+J12*Resumen!$C$7+K12*Resumen!$C$8 -> 0 | O12: =H12*N12 -> 0 | P12: =H12-O12 -> 135439 | Q12: =IF(L12>0,MIN(1,M12/L12,IF(K12=0,N12,1)),0) -> 0 | R12: =H12*Q12 -> 0 | S12: =IF(N12>0,H12,0) -> 0 | T12: =IF(N12>0,"Con entregas","Sin entregas") -> Sin entregas | U12: =I12*Resumen!$C$6+J12*Resumen!$C$7+K12*Resumen!$C$9 -> 0 | V12: =H12*U12 -> 0 | W12: =IF(COUNTIF(I12:K12,1)>0,1,0) -> 0 | X12: =COUNTIF(I12:K12,1)/3 -> 0 | Y12: =N12 -> 0 | Z12: =Y12-U12 -> 0 | AA12: El porcentaje reportado puede ser aporte al avance global; no necesariamente avance interno.
A13: 05628 | B13: Sabanalarga | C13: Occidente | D13: Provincia Occidente | E13: Original | F13: 26573 | H13: =IF(G13="",F13,G13) -> 26573 | I13: 0 | J13: 0 | K13: 0 | N13: =I13*Resumen!$C$6+J13*Resumen!$C$7+K13*Resumen!$C$8 -> 0 | O13: =H13*N13 -> 0 | P13: =H13-O13 -> 26573 | Q13: =IF(L13>0,MIN(1,M13/L13,IF(K13=0,N13,1)),0) -> 0 | R13: =H13*Q13 -> 0 | S13: =IF(N13>0,H13,0) -> 0 | T13: =IF(N13>0,"Con entregas","Sin entregas") -> Sin entregas | U13: =I13*Resumen!$C$6+J13*Resumen!$C$7+K13*Resumen!$C$9 -> 0 | V13: =H13*U13 -> 0 | W13: =IF(COUNTIF(I13:K13,1)>0,1,0) -> 0 | X13: =COUNTIF(I13:K13,1)/3 -> 0 | Y13: =N13 -> 0 | Z13: =Y13-U13 -> 0 | AA13: El porcentaje reportado puede ser aporte al avance global; no necesariamente avance interno.
A14: 05656 | B14: San Jerónimo | C14: Occidente | D14: Provincia Occidente | E14: Original | F14: 17256 | H14: =IF(G14="",F14,G14) -> 17256 | I14: 0 | J14: 0 | K14: 0 | N14: =I14*Resumen!$C$6+J14*Resumen!$C$7+K14*Resumen!$C$8 -> 0 | O14: =H14*N14 -> 0 | P14: =H14-O14 -> 17256 | Q14: =IF(L14>0,MIN(1,M14/L14,IF(K14=0,N14,1)),0) -> 0 | R14: =H14*Q14 -> 0 | S14: =IF(N14>0,H14,0) -> 0 | T14: =IF(N14>0,"Con entregas","Sin entregas") -> Sin entregas | U14: =I14*Resumen!$C$6+J14*Resumen!$C$7+K14*Resumen!$C$9 -> 0 | V14: =H14*U14 -> 0 | W14: =IF(COUNTIF(I14:K14,1)>0,1,0) -> 0 | X14: =COUNTIF(I14:K14,1)/3 -> 0 | Y14: =N14 -> 0 | Z14: =Y14-U14 -> 0 | AA14: El porcentaje reportado puede ser aporte al avance global; no necesariamente avance interno.
A15: 05042 | B15: Santa Fe de Antioquia | C15: Occidente | D15: Provincia Occidente | E15: Original | F15: 53607 | G15: 53606.96 | H15: =IF(G15="",F15,G15) -> 53606.96 | I15: 1 | J15: 1 | K15: 0 | L15: 0.0154 | M15: 0.0138 | N15: =I15*Resumen!$C$6+J15*Resumen!$C$7+K15*Resumen!$C$8 -> 0.9 | O15: =H15*N15 -> 48246.264 | P15: =H15-O15 -> 5360.696 | Q15: =IF(L15>0,MIN(1,M15/L15,IF(K15=0,N15,1)),0) -> 0.8961039 | R15: =H15*Q15 -> 48037.406 | S15: =IF(N15>0,H15,0) -> 53606.96 | T15: =IF(N15>0,"Con entregas","Sin entregas") -> Con entregas | U15: =I15*Resumen!$C$6+J15*Resumen!$C$7+K15*Resumen!$C$9 -> 0.9 | V15: =H15*U15 -> 48246.264 | W15: =IF(COUNTIF(I15:K15,1)>0,1,0) -> 1 | X15: =COUNTIF(I15:K15,1)/3 -> 0.66666667 | Y15: =N15 -> 0.9 | Z15: =Y15-U15 -> 0 | AA15: El porcentaje reportado puede ser aporte al avance global; no necesariamente avance interno.
A16: 05890 | B16: Yolombó | C16: Nordeste | D16: Provincia Mineros | E16: Original | F16: 94340 | H16: =IF(G16="",F16,G16) -> 94340 | I16: 0 | J16: 0 | K16: 0 | N16: =I16*Resumen!$C$6+J16*Resumen!$C$7+K16*Resumen!$C$8 -> 0 | O16: =H16*N16 -> 0 | P16: =H16-O16 -> 94340 | Q16: =IF(L16>0,MIN(1,M16/L16,IF(K16=0,N16,1)),0) -> 0 | R16: =H16*Q16 -> 0 | S16: =IF(N16>0,H16,0) -> 0 | T16: =IF(N16>0,"Con entregas","Sin entregas") -> Sin entregas | U16: =I16*Resumen!$C$6+J16*Resumen!$C$7+K16*Resumen!$C$9 -> 0 | V16: =H16*U16 -> 0 | W16: =IF(COUNTIF(I16:K16,1)>0,1,0) -> 0 | X16: =COUNTIF(I16:K16,1)/3 -> 0 | Y16: =N16 -> 0 | Z16: =Y16-U16 -> 0 | AA16: El porcentaje reportado puede ser aporte al avance global; no necesariamente avance interno.
A17: 05002 | B17: Abejorral | C17: Oriente | D17: Sin provincia asignada | E17: Original | F17: 50695 | G17: 50695.28 | H17: =IF(G17="",F17,G17) -> 50695.28 | I17: 0 | J17: 1 | K17: 0 | L17: 0.0145 | M17: 0.0052 | N17: =I17*Resumen!$C$6+J17*Resumen!$C$7+K17*Resumen!$C$8 -> 0.45 | O17: =H17*N17 -> 22812.876 | P17: =H17-O17 -> 27882.404 | Q17: =IF(L17>0,MIN(1,M17/L17,IF(K17=0,N17,1)),0) -> 0.35862069 | R17: =H17*Q17 -> 18180.376 | S17: =IF(N17>0,H17,0) -> 50695.28 | T17: =IF(N17>0,"Con entregas","Sin entregas") -> Con entregas | U17: =I17*Resumen!$C$6+J17*Resumen!$C$7+K17*Resumen!$C$9 -> 0.45 | V17: =H17*U17 -> 22812.876 | W17: =IF(COUNTIF(I17:K17,1)>0,1,0) -> 1 | X17: =COUNTIF(I17:K17,1)/3 -> 0.33333333 | Y17: =N17 -> 0.45 | Z17: =Y17-U17 -> 0 | AA17: El porcentaje reportado puede ser aporte al avance global; no necesariamente avance interno.
A18: 05004 | B18: Abriaquí | C18: Occidente | D18: Sin provincia asignada | E18: Original | F18: 29715 | H18: =IF(G18="",F18,G18) -> 29715 | I18: 0 | J18: 0 | K18: 0 | N18: =I18*Resumen!$C$6+J18*Resumen!$C$7+K18*Resumen!$C$8 -> 0 | O18: =H18*N18 -> 0 | P18: =H18-O18 -> 29715 | Q18: =IF(L18>0,MIN(1,M18/L18,IF(K18=0,N18,1)),0) -> 0 | R18: =H18*Q18 -> 0 | S18: =IF(N18>0,H18,0) -> 0 | T18: =IF(N18>0,"Con entregas","Sin entregas") -> Sin entregas | U18: =I18*Resumen!$C$6+J18*Resumen!$C$7+K18*Resumen!$C$9 -> 0 | V18: =H18*U18 -> 0 | W18: =IF(COUNTIF(I18:K18,1)>0,1,0) -> 0 | X18: =COUNTIF(I18:K18,1)/3 -> 0 | Y18: =N18 -> 0 | Z18: =Y18-U18 -> 0 | AA18: El porcentaje reportado puede ser aporte al avance global; no necesariamente avance interno.
A19: 05031 | B19: Amalfi | C19: Nordeste | D19: Sin provincia asignada | E19: Original | F19: 120835 | G19: 120834.62 | H19: =IF(G19="",F19,G19) -> 120834.62 | I19: 1 | J19: 0 | K19: 0 | L19: 0.0346 | M19: 0.0156 | N19: =I19*Resumen!$C$6+J19*Resumen!$C$7+K19*Resumen!$C$8 -> 0.45 | O19: =H19*N19 -> 54375.579 | P19: =H19-O19 -> 66459.041 | Q19: =IF(L19>0,MIN(1,M19/L19,IF(K19=0,N19,1)),0) -> 0.45 | R19: =H19*Q19 -> 54375.579 | S19: =IF(N19>0,H19,0) -> 120834.62 | T19: =IF(N19>0,"Con entregas","Sin entregas") -> Con entregas | U19: =I19*Resumen!$C$6+J19*Resumen!$C$7+K19*Resumen!$C$9 -> 0.45 | V19: =H19*U19 -> 54375.579 | W19: =IF(COUNTIF(I19:K19,1)>0,1,0) -> 1 | X19: =COUNTIF(I19:K19,1)/3 -> 0.33333333 | Y19: =N19 -> 0.45 | Z19: =Y19-U19 -> 0 | AA19: El porcentaje reportado puede ser aporte al avance global; no necesariamente avance interno.
A20: 05059 | B20: Armenia | C20: Occidente | D20: Sin provincia asignada | E20: Original | F20: 11050 | G20: 11050.26 | H20: =IF(G20="",F20,G20) -> 11050.26 | I20: 0 | J20: 1 | K20: 0 | L20: 0.0032 | M20: 0.001 | N20: =I20*Resumen!$C$6+J20*Resumen!$C$7+K20*Resumen!$C$8 -> 0.45 | O20: =H20*N20 -> 4972.617 | P20: =H20-O20 -> 6077.643 | Q20: =IF(L20>0,MIN(1,M20/L20,IF(K20=0,N20,1)),0) -> 0.3125 | R20: =H20*Q20 -> 3453.2063 | S20: =IF(N20>0,H20,0) -> 11050.26 | T20: =IF(N20>0,"Con entregas","Sin entregas") -> Con entregas | U20: =I20*Resumen!$C$6+J20*Resumen!$C$7+K20*Resumen!$C$9 -> 0.45 | V20: =H20*U20 -> 4972.617 | W20: =IF(COUNTIF(I20:K20,1)>0,1,0) -> 1 | X20: =COUNTIF(I20:K20,1)/3 -> 0.33333333 | Y20: =N20 -> 0.45 | Z20: =Y20-U20 -> 0 | AA20: El porcentaje reportado puede ser aporte al avance global; no necesariamente avance interno.
A21: 05086 | B21: Belmira | C21: Norte | D21: Sin provincia asignada | E21: Original | F21: 30466 | H21: =IF(G21="",F21,G21) -> 30466 | I21: 0 | J21: 0 | K21: 0 | N21: =I21*Resumen!$C$6+J21*Resumen!$C$7+K21*Resumen!$C$8 -> 0 | O21: =H21*N21 -> 0 | P21: =H21-O21 -> 30466 | Q21: =IF(L21>0,MIN(1,M21/L21,IF(K21=0,N21,1)),0) -> 0 | R21: =H21*Q21 -> 0 | S21: =IF(N21>0,H21,0) -> 0 | T21: =IF(N21>0,"Con entregas","Sin entregas") -> Sin entregas | U21: =I21*Resumen!$C$6+J21*Resumen!$C$7+K21*Resumen!$C$9 -> 0 | V21: =H21*U21 -> 0 | W21: =IF(COUNTIF(I21:K21,1)>0,1,0) -> 0 | X21: =COUNTIF(I21:K21,1)/3 -> 0 | Y21: =N21 -> 0 | Z21: =Y21-U21 -> 0 | AA21: El porcentaje reportado puede ser aporte al avance global; no necesariamente avance interno.
A22: 05107 | B22: Briceño | C22: Norte | D22: Sin provincia asignada | E22: Original | F22: 37624 | H22: =IF(G22="",F22,G22) -> 37624 | I22: 0 | J22: 0 | K22: 0 | N22: =I22*Resumen!$C$6+J22*Resumen!$C$7+K22*Resumen!$C$8 -> 0 | O22: =H22*N22 -> 0 | P22: =H22-O22 -> 37624 | Q22: =IF(L22>0,MIN(1,M22/L22,IF(K22=0,N22,1)),0) -> 0 | R22: =H22*Q22 -> 0 | S22: =IF(N22>0,H22,0) -> 0 | T22: =IF(N22>0,"Con entregas","Sin entregas") -> Sin entregas | U22: =I22*Resumen!$C$6+J22*Resumen!$C$7+K22*Resumen!$C$9 -> 0 | V22: =H22*U22 -> 0 | W22: =IF(COUNTIF(I22:K22,1)>0,1,0) -> 0 | X22: =COUNTIF(I22:K22,1)/3 -> 0 | Y22: =N22 -> 0 | Z22: =Y22-U22 -> 0 | AA22: El porcentaje reportado puede ser aporte al avance global; no necesariamente avance interno.
A23: 05113 | B23: Buriticá | C23: Occidente | D23: Sin provincia asignada | E23: Original | F23: 35519 | H23: =IF(G23="",F23,G23) -> 35519 | I23: 0 | J23: 0 | K23: 0 | N23: =I23*Resumen!$C$6+J23*Resumen!$C$7+K23*Resumen!$C$8 -> 0 | O23: =H23*N23 -> 0 | P23: =H23-O23 -> 35519 | Q23: =IF(L23>0,MIN(1,M23/L23,IF(K23=0,N23,1)),0) -> 0 | R23: =H23*Q23 -> 0 | S23: =IF(N23>0,H23,0) -> 0 | T23: =IF(N23>0,"Con entregas","Sin entregas") -> Sin entregas | U23: =I23*Resumen!$C$6+J23*Resumen!$C$7+K23*Resumen!$C$9 -> 0 | V23: =H23*U23 -> 0 | W23: =IF(COUNTIF(I23:K23,1)>0,1,0) -> 0 | X23: =COUNTIF(I23:K23,1)/3 -> 0 | Y23: =N23 -> 0 | Z23: =Y23-U23 -> 0 | AA23: El porcentaje reportado puede ser aporte al avance global; no necesariamente avance interno.
A24: 05134 | B24: Campamento | C24: Norte | D24: Sin provincia asignada | E24: Original | F24: 23206 | H24: =IF(G24="",F24,G24) -> 23206 | I24: 0 | J24: 0 | K24: 0 | N24: =I24*Resumen!$C$6+J24*Resumen!$C$7+K24*Resumen!$C$8 -> 0 | O24: =H24*N24 -> 0 | P24: =H24-O24 -> 23206 | Q24: =IF(L24>0,MIN(1,M24/L24,IF(K24=0,N24,1)),0) -> 0 | R24: =H24*Q24 -> 0 | S24: =IF(N24>0,H24,0) -> 0 | T24: =IF(N24>0,"Con entregas","Sin entregas") -> Sin entregas | U24: =I24*Resumen!$C$6+J24*Resumen!$C$7+K24*Resumen!$C$9 -> 0 | V24: =H24*U24 -> 0 | W24: =IF(COUNTIF(I24:K24,1)>0,1,0) -> 0 | X24: =COUNTIF(I24:K24,1)/3 -> 0 | Y24: =N24 -> 0 | Z24: =Y24-U24 -> 0 | AA24: El porcentaje reportado puede ser aporte al avance global; no necesariamente avance interno.
A25: 05142 | B25: Caracolí | C25: Magdalena Medio | D25: Sin provincia asignada | E25: Original | F25: 26258 | H25: =IF(G25="",F25,G25) -> 26258 | I25: 0 | J25: 0 | K25: 0 | N25: =I25*Resumen!$C$6+J25*Resumen!$C$7+K25*Resumen!$C$8 -> 0 | O25: =H25*N25 -> 0 | P25: =H25-O25 -> 26258 | Q25: =IF(L25>0,MIN(1,M25/L25,IF(K25=0,N25,1)),0) -> 0 | R25: =H25*Q25 -> 0 | S25: =IF(N25>0,H25,0) -> 0 | T25: =IF(N25>0,"Con entregas","Sin entregas") -> Sin entregas | U25: =I25*Resumen!$C$6+J25*Resumen!$C$7+K25*Resumen!$C$9 -> 0 | V25: =H25*U25 -> 0 | W25: =IF(COUNTIF(I25:K25,1)>0,1,0) -> 0 | X25: =COUNTIF(I25:K25,1)/3 -> 0 | Y25: =N25 -> 0 | Z25: =Y25-U25 -> 0 | AA25: El porcentaje reportado puede ser aporte al avance global; no necesariamente avance interno.
A26: 05154 | B26: Caucasia | C26: Bajo Cauca | D26: Sin provincia asignada | E26: Original | F26: 169909 | H26: =IF(G26="",F26,G26) -> 169909 | I26: 0 | J26: 0 | K26: 0 | N26: =I26*Resumen!$C$6+J26*Resumen!$C$7+K26*Resumen!$C$8 -> 0 | O26: =H26*N26 -> 0 | P26: =H26-O26 -> 169909 | Q26: =IF(L26>0,MIN(1,M26/L26,IF(K26=0,N26,1)),0) -> 0 | R26: =H26*Q26 -> 0 | S26: =IF(N26>0,H26,0) -> 0 | T26: =IF(N26>0,"Con entregas","Sin entregas") -> Sin entregas | U26: =I26*Resumen!$C$6+J26*Resumen!$C$7+K26*Resumen!$C$9 -> 0 | V26: =H26*U26 -> 0 | W26: =IF(COUNTIF(I26:K26,1)>0,1,0) -> 0 | X26: =COUNTIF(I26:K26,1)/3 -> 0 | Y26: =N26 -> 0 | Z26: =Y26-U26 -> 0 | AA26: El porcentaje reportado puede ser aporte al avance global; no necesariamente avance interno.
A27: 05138 | B27: Cañasgordas | C27: Occidente | D27: Sin provincia asignada | E27: Original | F27: 36484 | H27: =IF(G27="",F27,G27) -> 36484 | I27: 0 | J27: 0 | K27: 0 | N27: =I27*Resumen!$C$6+J27*Resumen!$C$7+K27*Resumen!$C$8 -> 0 | O27: =H27*N27 -> 0 | P27: =H27-O27 -> 36484 | Q27: =IF(L27>0,MIN(1,M27/L27,IF(K27=0,N27,1)),0) -> 0 | R27: =H27*Q27 -> 0 | S27: =IF(N27>0,H27,0) -> 0 | T27: =IF(N27>0,"Con entregas","Sin entregas") -> Sin entregas | U27: =I27*Resumen!$C$6+J27*Resumen!$C$7+K27*Resumen!$C$9 -> 0 | V27: =H27*U27 -> 0 | W27: =IF(COUNTIF(I27:K27,1)>0,1,0) -> 0 | X27: =COUNTIF(I27:K27,1)/3 -> 0 | Y27: =N27 -> 0 | Z27: =Y27-U27 -> 0 | AA27: El porcentaje reportado puede ser aporte al avance global; no necesariamente avance interno.
A28: 05172 | B28: Chigorodó | C28: Urabá | D28: Sin provincia asignada | E28: Original | F28: 76629 | H28: =IF(G28="",F28,G28) -> 76629 | I28: 0 | J28: 0 | K28: 0 | N28: =I28*Resumen!$C$6+J28*Resumen!$C$7+K28*Resumen!$C$8 -> 0 | O28: =H28*N28 -> 0 | P28: =H28-O28 -> 76629 | Q28: =IF(L28>0,MIN(1,M28/L28,IF(K28=0,N28,1)),0) -> 0 | R28: =H28*Q28 -> 0 | S28: =IF(N28>0,H28,0) -> 0 | T28: =IF(N28>0,"Con entregas","Sin entregas") -> Sin entregas | U28: =I28*Resumen!$C$6+J28*Resumen!$C$7+K28*Resumen!$C$9 -> 0 | V28: =H28*U28 -> 0 | W28: =IF(COUNTIF(I28:K28,1)>0,1,0) -> 0 | X28: =COUNTIF(I28:K28,1)/3 -> 0 | Y28: =N28 -> 0 | Z28: =Y28-U28 -> 0 | AA28: El porcentaje reportado puede ser aporte al avance global; no necesariamente avance interno.
A29: 05190 | B29: Cisneros | C29: Nordeste | D29: Sin provincia asignada | E29: Original | F29: 4691 | G29: 4691.49 | H29: =IF(G29="",F29,G29) -> 4691.49 | I29: 1 | J29: 1 | K29: 0 | L29: 0.0013 | M29: 0.0012 | N29: =I29*Resumen!$C$6+J29*Resumen!$C$7+K29*Resumen!$C$8 -> 0.9 | O29: =H29*N29 -> 4222.341 | P29: =H29-O29 -> 469.149 | Q29: =IF(L29>0,MIN(1,M29/L29,IF(K29=0,N29,1)),0) -> 0.9 | R29: =H29*Q29 -> 4222.341 | S29: =IF(N29>0,H29,0) -> 4691.49 | T29: =IF(N29>0,"Con entregas","Sin entregas") -> Con entregas | U29: =I29*Resumen!$C$6+J29*Resumen!$C$7+K29*Resumen!$C$9 -> 0.9 | V29: =H29*U29 -> 4222.341 | W29: =IF(COUNTIF(I29:K29,1)>0,1,0) -> 1 | X29: =COUNTIF(I29:K29,1)/3 -> 0.66666667 | Y29: =N29 -> 0.9 | Z29: =Y29-U29 -> 0 | AA29: El porcentaje reportado puede ser aporte al avance global; no necesariamente avance interno.
A30: 05234 | B30: Dabeiba | C30: Occidente | D30: Sin provincia asignada | E30: Original | F30: 195844 | H30: =IF(G30="",F30,G30) -> 195844 | I30: 0 | J30: 0 | K30: 0 | N30: =I30*Resumen!$C$6+J30*Resumen!$C$7+K30*Resumen!$C$8 -> 0 | O30: =H30*N30 -> 0 | P30: =H30-O30 -> 195844 | Q30: =IF(L30>0,MIN(1,M30/L30,IF(K30=0,N30,1)),0) -> 0 | R30: =H30*Q30 -> 0 | S30: =IF(N30>0,H30,0) -> 0 | T30: =IF(N30>0,"Con entregas","Sin entregas") -> Sin entregas | U30: =I30*Resumen!$C$6+J30*Resumen!$C$7+K30*Resumen!$C$9 -> 0 | V30: =H30*U30 -> 0 | W30: =IF(COUNTIF(I30:K30,1)>0,1,0) -> 0 | X30: =COUNTIF(I30:K30,1)/3 -> 0 | Y30: =N30 -> 0 | Z30: =Y30-U30 -> 0 | AA30: El porcentaje reportado puede ser aporte al avance global; no necesariamente avance interno.
A31: 05240 | B31: Ebéjico | C31: Occidente | D31: Sin provincia asignada | E31: Original | F31: 24687 | H31: =IF(G31="",F31,G31) -> 24687 | I31: 0 | J31: 0 | K31: 0 | N31: =I31*Resumen!$C$6+J31*Resumen!$C$7+K31*Resumen!$C$8 -> 0 | O31: =H31*N31 -> 0 | P31: =H31-O31 -> 24687 | Q31: =IF(L31>0,MIN(1,M31/L31,IF(K31=0,N31,1)),0) -> 0 | R31: =H31*Q31 -> 0 | S31: =IF(N31>0,H31,0) -> 0 | T31: =IF(N31>0,"Con entregas","Sin entregas") -> Sin entregas | U31: =I31*Resumen!$C$6+J31*Resumen!$C$7+K31*Resumen!$C$9 -> 0 | V31: =H31*U31 -> 0 | W31: =IF(COUNTIF(I31:K31,1)>0,1,0) -> 0 | X31: =COUNTIF(I31:K31,1)/3 -> 0 | Y31: =N31 -> 0 | Z31: =Y31-U31 -> 0 | AA31: El porcentaje reportado puede ser aporte al avance global; no necesariamente avance interno.
A32: 05264 | B32: Entrerríos | C32: Norte | D32: Sin provincia asignada | E32: Original | F32: 21414 | G32: 21413.54 | H32: =IF(G32="",F32,G32) -> 21413.54 | I32: 1 | J32: 1 | K32: 0 | L32: 0.0061 | M32: 0.0032 | N32: =I32*Resumen!$C$6+J32*Resumen!$C$7+K32*Resumen!$C$8 -> 0.9 | O32: =H32*N32 -> 19272.186 | P32: =H32-O32 -> 2141.354 | Q32: =IF(L32>0,MIN(1,M32/L32,IF(K32=0,N32,1)),0) -> 0.52459016 | R32: =H32*Q32 -> 11233.332 | S32: =IF(N32>0,H32,0) -> 21413.54 | T32: =IF(N32>0,"Con entregas","Sin entregas") -> Con entregas | U32: =I32*Resumen!$C$6+J32*Resumen!$C$7+K32*Resumen!$C$9 -> 0.9 | V32: =H32*U32 -> 19272.186 | W32: =IF(COUNTIF(I32:K32,1)>0,1,0) -> 1 | X32: =COUNTIF(I32:K32,1)/3 -> 0.66666667 | Y32: =N32 -> 0.9 | Z32: =Y32-U32 -> 0 | AA32: El porcentaje reportado puede ser aporte al avance global; no necesariamente avance interno.
A33: 05284 | B33: Frontino | C33: Occidente | D33: Sin provincia asignada | E33: Original | F33: 142539 | H33: =IF(G33="",F33,G33) -> 142539 | I33: 0 | J33: 0 | K33: 0 | N33: =I33*Resumen!$C$6+J33*Resumen!$C$7+K33*Resumen!$C$8 -> 0 | O33: =H33*N33 -> 0 | P33: =H33-O33 -> 142539 | Q33: =IF(L33>0,MIN(1,M33/L33,IF(K33=0,N33,1)),0) -> 0 | R33: =H33*Q33 -> 0 | S33: =IF(N33>0,H33,0) -> 0 | T33: =IF(N33>0,"Con entregas","Sin entregas") -> Sin entregas | U33: =I33*Resumen!$C$6+J33*Resumen!$C$7+K33*Resumen!$C$9 -> 0 | V33: =H33*U33 -> 0 | W33: =IF(COUNTIF(I33:K33,1)>0,1,0) -> 0 | X33: =COUNTIF(I33:K33,1)/3 -> 0 | Y33: =N33 -> 0 | Z33: =Y33-U33 -> 0 | AA33: El porcentaje reportado puede ser aporte al avance global; no necesariamente avance interno.
A34: 05306 | B34: Giraldo | C34: Occidente | D34: Sin provincia asignada | E34: Original | F34: 9349 | H34: =IF(G34="",F34,G34) -> 9349 | I34: 0 | J34: 0 | K34: 0 | N34: =I34*Resumen!$C$6+J34*Resumen!$C$7+K34*Resumen!$C$8 -> 0 | O34: =H34*N34 -> 0 | P34: =H34-O34 -> 9349 | Q34: =IF(L34>0,MIN(1,M34/L34,IF(K34=0,N34,1)),0) -> 0 | R34: =H34*Q34 -> 0 | S34: =IF(N34>0,H34,0) -> 0 | T34: =IF(N34>0,"Con entregas","Sin entregas") -> Sin entregas | U34: =I34*Resumen!$C$6+J34*Resumen!$C$7+K34*Resumen!$C$9 -> 0 | V34: =H34*U34 -> 0 | W34: =IF(COUNTIF(I34:K34,1)>0,1,0) -> 0 | X34: =COUNTIF(I34:K34,1)/3 -> 0 | Y34: =N34 -> 0 | Z34: =Y34-U34 -> 0 | AA34: El porcentaje reportado puede ser aporte al avance global; no necesariamente avance interno.
A35: 05315 | B35: Guadalupe | C35: Norte | D35: Sin provincia asignada | E35: Original | F35: 11825 | H35: =IF(G35="",F35,G35) -> 11825 | I35: 0 | J35: 0 | K35: 0 | N35: =I35*Resumen!$C$6+J35*Resumen!$C$7+K35*Resumen!$C$8 -> 0 | O35: =H35*N35 -> 0 | P35: =H35-O35 -> 11825 | Q35: =IF(L35>0,MIN(1,M35/L35,IF(K35=0,N35,1)),0) -> 0 | R35: =H35*Q35 -> 0 | S35: =IF(N35>0,H35,0) -> 0 | T35: =IF(N35>0,"Con entregas","Sin entregas") -> Sin entregas | U35: =I35*Resumen!$C$6+J35*Resumen!$C$7+K35*Resumen!$C$9 -> 0 | V35: =H35*U35 -> 0 | W35: =IF(COUNTIF(I35:K35,1)>0,1,0) -> 0 | X35: =COUNTIF(I35:K35,1)/3 -> 0 | Y35: =N35 -> 0 | Z35: =Y35-U35 -> 0 | AA35: El porcentaje reportado puede ser aporte al avance global; no necesariamente avance interno.
A36: 05347 | B36: Heliconia | C36: Occidente | D36: Sin provincia asignada | E36: Original | F36: 11493 | H36: =IF(G36="",F36,G36) -> 11493 | I36: 0 | J36: 0 | K36: 0 | N36: =I36*Resumen!$C$6+J36*Resumen!$C$7+K36*Resumen!$C$8 -> 0 | O36: =H36*N36 -> 0 | P36: =H36-O36 -> 11493 | Q36: =IF(L36>0,MIN(1,M36/L36,IF(K36=0,N36,1)),0) -> 0 | R36: =H36*Q36 -> 0 | S36: =IF(N36>0,H36,0) -> 0 | T36: =IF(N36>0,"Con entregas","Sin entregas") -> Sin entregas | U36: =I36*Resumen!$C$6+J36*Resumen!$C$7+K36*Resumen!$C$9 -> 0 | V36: =H36*U36 -> 0 | W36: =IF(COUNTIF(I36:K36,1)>0,1,0) -> 0 | X36: =COUNTIF(I36:K36,1)/3 -> 0 | Y36: =N36 -> 0 | Z36: =Y36-U36 -> 0 | AA36: El porcentaje reportado puede ser aporte al avance global; no necesariamente avance interno.
A37: 05411 | B37: Liborina | C37: Occidente | D37: Sin provincia asignada | E37: Original | F37: 21639 | H37: =IF(G37="",F37,G37) -> 21639 | I37: 0 | J37: 0 | K37: 0 | N37: =I37*Resumen!$C$6+J37*Resumen!$C$7+K37*Resumen!$C$8 -> 0 | O37: =H37*N37 -> 0 | P37: =H37-O37 -> 21639 | Q37: =IF(L37>0,MIN(1,M37/L37,IF(K37=0,N37,1)),0) -> 0 | R37: =H37*Q37 -> 0 | S37: =IF(N37>0,H37,0) -> 0 | T37: =IF(N37>0,"Con entregas","Sin entregas") -> Sin entregas | U37: =I37*Resumen!$C$6+J37*Resumen!$C$7+K37*Resumen!$C$9 -> 0 | V37: =H37*U37 -> 0 | W37: =IF(COUNTIF(I37:K37,1)>0,1,0) -> 0 | X37: =COUNTIF(I37:K37,1)/3 -> 0 | Y37: =N37 -> 0 | Z37: =Y37-U37 -> 0 | AA37: El porcentaje reportado puede ser aporte al avance global; no necesariamente avance interno.
A38: 05425 | B38: Maceo | C38: Magdalena Medio | D38: Sin provincia asignada | E38: Original | F38: 45529 | H38: =IF(G38="",F38,G38) -> 45529 | I38: 0 | J38: 0 | K38: 0 | N38: =I38*Resumen!$C$6+J38*Resumen!$C$7+K38*Resumen!$C$8 -> 0 | O38: =H38*N38 -> 0 | P38: =H38-O38 -> 45529 | Q38: =IF(L38>0,MIN(1,M38/L38,IF(K38=0,N38,1)),0) -> 0 | R38: =H38*Q38 -> 0 | S38: =IF(N38>0,H38,0) -> 0 | T38: =IF(N38>0,"Con entregas","Sin entregas") -> Sin entregas | U38: =I38*Resumen!$C$6+J38*Resumen!$C$7+K38*Resumen!$C$9 -> 0 | V38: =H38*U38 -> 0 | W38: =IF(COUNTIF(I38:K38,1)>0,1,0) -> 0 | X38: =COUNTIF(I38:K38,1)/3 -> 0 | Y38: =N38 -> 0 | Z38: =Y38-U38 -> 0 | AA38: El porcentaje reportado puede ser aporte al avance global; no necesariamente avance interno.
A39: 05480 | B39: Mutatá | C39: Urabá | D39: Sin provincia asignada | E39: Original | F39: 109140 | H39: =IF(G39="",F39,G39) -> 109140 | I39: 0 | J39: 0 | K39: 0 | N39: =I39*Resumen!$C$6+J39*Resumen!$C$7+K39*Resumen!$C$8 -> 0 | O39: =H39*N39 -> 0 | P39: =H39-O39 -> 109140 | Q39: =IF(L39>0,MIN(1,M39/L39,IF(K39=0,N39,1)),0) -> 0 | R39: =H39*Q39 -> 0 | S39: =IF(N39>0,H39,0) -> 0 | T39: =IF(N39>0,"Con entregas","Sin entregas") -> Sin entregas | U39: =I39*Resumen!$C$6+J39*Resumen!$C$7+K39*Resumen!$C$9 -> 0 | V39: =H39*U39 -> 0 | W39: =IF(COUNTIF(I39:K39,1)>0,1,0) -> 0 | X39: =COUNTIF(I39:K39,1)/3 -> 0 | Y39: =N39 -> 0 | Z39: =Y39-U39 -> 0 | AA39: El porcentaje reportado puede ser aporte al avance global; no necesariamente avance interno.
A40: 05490 | B40: Necoclí | C40: Urabá | D40: Sin provincia asignada | E40: Original | F40: 126064 | G40: 126063.91 | H40: =IF(G40="",F40,G40) -> 126063.91 | I40: 0 | J40: 1 | K40: 0 | L40: 0.0361 | M40: 0.0135 | N40: =I40*Resumen!$C$6+J40*Resumen!$C$7+K40*Resumen!$C$8 -> 0.45 | O40: =H40*N40 -> 56728.76 | P40: =H40-O40 -> 69335.151 | Q40: =IF(L40>0,MIN(1,M40/L40,IF(K40=0,N40,1)),0) -> 0.37396122 | R40: =H40*Q40 -> 47143.013 | S40: =IF(N40>0,H40,0) -> 126063.91 | T40: =IF(N40>0,"Con entregas","Sin entregas") -> Con entregas | U40: =I40*Resumen!$C$6+J40*Resumen!$C$7+K40*Resumen!$C$9 -> 0.45 | V40: =H40*U40 -> 56728.76 | W40: =IF(COUNTIF(I40:K40,1)>0,1,0) -> 1 | X40: =COUNTIF(I40:K40,1)/3 -> 0.33333333 | Y40: =N40 -> 0.45 | Z40: =Y40-U40 -> 0 | AA40: El porcentaje reportado puede ser aporte al avance global; no necesariamente avance interno.
A41: 05501 | B41: Olaya | C41: Occidente | D41: Sin provincia asignada | E41: Original | F41: 9952 | G41: 9952.2 | H41: =IF(G41="",F41,G41) -> 9952.2 | I41: 1 | J41: 1 | K41: 0 | L41: 0.0029 | M41: 0.0026 | N41: =I41*Resumen!$C$6+J41*Resumen!$C$7+K41*Resumen!$C$8 -> 0.9 | O41: =H41*N41 -> 8956.98 | P41: =H41-O41 -> 995.22 | Q41: =IF(L41>0,MIN(1,M41/L41,IF(K41=0,N41,1)),0) -> 0.89655172 | R41: =H41*Q41 -> 8922.6621 | S41: =IF(N41>0,H41,0) -> 9952.2 | T41: =IF(N41>0,"Con entregas","Sin entregas") -> Con entregas | U41: =I41*Resumen!$C$6+J41*Resumen!$C$7+K41*Resumen!$C$9 -> 0.9 | V41: =H41*U41 -> 8956.98 | W41: =IF(COUNTIF(I41:K41,1)>0,1,0) -> 1 | X41: =COUNTIF(I41:K41,1)/3 -> 0.66666667 | Y41: =N41 -> 0.9 | Z41: =Y41-U41 -> 0 | AA41: El porcentaje reportado puede ser aporte al avance global; no necesariamente avance interno.
...

Sheet Urbano_2024
A1: Cartografía urbana · corte 31-dic-2024
A2: Informe de avance N°8 (dic-2024), Valor+, Contrato 24MA176H1682. Área contrato: Tablas 2-3 págs. 8-9. Entregas, importancia y % conforme: Tabla 25 págs. 44-45 (rural) y Tabla 28 págs. 51-52 (urbano). Azul = dato transcrito; negro = fórmula.
A4: Cód. DANE | B4: Municipio | C4: Región | D4: Provincia | E4: Alcance | F4: Área contrato (ha) | G4: Área según interventoría (ha) | H4: Área base (ha) | I4: Ortofoto entregada (1/0) | J4: MDT entregado (1/0) | K4: Vectorial entregado (1/0) | L4: Importancia reportada (%) | M4: % conforme reportado | N4: % avance entregado | O4: Ha equivalentes entregadas | P4: Ha pendientes | Q4: % conforme del municipio | R4: Ha equivalentes conformes | S4: Área bruta con entregas (ha) | T4: Estado | U4: Avance ponderado contractual (45/45/10) | V4: Ha equivalentes ponderadas | W4: Cobertura territorial ≥1 producto | X4: Avance por conteo simple | Y4: Porcentaje reportado por informe | Z4: Diferencia reporte-cálculo | AA4: Observación
A5: 05197 | B5: Cocorná | C5: Oriente | D5: Provincia ABT | E5: Original | F5: 87.1 | G5: 99.63 | H5: =IF(G5="",F5,G5) -> 99.63 | I5: 1 | J5: 1 | K5: 0 | L5: 0.0113 | M5: 0.0102 | N5: =I5*Resumen!$C$6+J5*Resumen!$C$7+K5*Resumen!$C$8 -> 0.9 | O5: =H5*N5 -> 89.667 | P5: =H5-O5 -> 9.963 | Q5: =IF(L5>0,MIN(1,M5/L5,IF(K5=0,N5,1)),0) -> 0.9 | R5: =H5*Q5 -> 89.667 | S5: =IF(N5>0,H5,0) -> 99.63 | T5: =IF(N5>0,"Con entregas","Sin entregas") -> Con entregas | U5: =I5*Resumen!$C$6+J5*Resumen!$C$7+K5*Resumen!$C$9 -> 0.9 | V5: =H5*U5 -> 89.667 | W5: =IF(COUNTIF(I5:K5,1)>0,1,0) -> 1 | X5: =COUNTIF(I5:K5,1)/3 -> 0.66666667 | Y5: =N5 -> 0.9 | Z5: =Y5-U5 -> 0 | AA5: El porcentaje reportado puede ser aporte al avance global; no necesariamente avance interno.
A6: 05206 | B6: Concepción | C6: Oriente | D6: Provincia ABT | E6: Original | F6: 33.8 | H6: =IF(G6="",F6,G6) -> 33.8 | I6: 0 | J6: 0 | K6: 0 | N6: =I6*Resumen!$C$6+J6*Resumen!$C$7+K6*Resumen!$C$8 -> 0 | O6: =H6*N6 -> 0 | P6: =H6-O6 -> 33.8 | Q6: =IF(L6>0,MIN(1,M6/L6,IF(K6=0,N6,1)),0) -> 0 | R6: =H6*Q6 -> 0 | S6: =IF(N6>0,H6,0) -> 0 | T6: =IF(N6>0,"Con entregas","Sin entregas") -> Sin entregas | U6: =I6*Resumen!$C$6+J6*Resumen!$C$7+K6*Resumen!$C$9 -> 0 | V6: =H6*U6 -> 0 | W6: =IF(COUNTIF(I6:K6,1)>0,1,0) -> 0 | X6: =COUNTIF(I6:K6,1)/3 -> 0 | Y6: =N6 -> 0 | Z6: =Y6-U6 -> 0 | AA6: El porcentaje reportado puede ser aporte al avance global; no necesariamente avance interno.
A7: 05649 | B7: San Carlos | C7: Oriente | D7: Provincia ABT | E7: Original | F7: 300.3 | G7: 243.43 | H7: =IF(G7="",F7,G7) -> 243.43 | I7: 1 | J7: 1 | K7: 1 | L7: 0.0277 | M7: 0.027 | N7: =I7*Resumen!$C$6+J7*Resumen!$C$7+K7*Resumen!$C$8 -> 0.9 | O7: =H7*N7 -> 219.087 | P7: =H7-O7 -> 24.343 | Q7: =IF(L7>0,MIN(1,M7/L7,IF(K7=0,N7,1)),0) -> 0.97472924 | R7: =H7*Q7 -> 237.27834 | S7: =IF(N7>0,H7,0) -> 243.43 | T7: =IF(N7>0,"Con entregas","Sin entregas") -> Con entregas | U7: =I7*Resumen!$C$6+J7*Resumen!$C$7+K7*Resumen!$C$9 -> 1 | V7: =H7*U7 -> 243.43 | W7: =IF(COUNTIF(I7:K7,1)>0,1,0) -> 1 | X7: =COUNTIF(I7:K7,1)/3 -> 1 | Y7: =N7 -> 0.9 | Z7: =Y7-U7 -> -0.1 | AA7: El porcentaje reportado puede ser aporte al avance global; no necesariamente avance interno.
A8: 05310 | B8: Gómez Plata | C8: Norte | D8: Provincia Bio-Energética del Norte | E8: Original | F8: 83.2 | H8: =IF(G8="",F8,G8) -> 83.2 | I8: 0 | J8: 0 | K8: 0 | N8: =I8*Resumen!$C$6+J8*Resumen!$C$7+K8*Resumen!$C$8 -> 0 | O8: =H8*N8 -> 0 | P8: =H8-O8 -> 83.2 | Q8: =IF(L8>0,MIN(1,M8/L8,IF(K8=0,N8,1)),0) -> 0 | R8: =H8*Q8 -> 0 | S8: =IF(N8>0,H8,0) -> 0 | T8: =IF(N8>0,"Con entregas","Sin entregas") -> Sin entregas | U8: =I8*Resumen!$C$6+J8*Resumen!$C$7+K8*Resumen!$C$9 -> 0 | V8: =H8*U8 -> 0 | W8: =IF(COUNTIF(I8:K8,1)>0,1,0) -> 0 | X8: =COUNTIF(I8:K8,1)/3 -> 0 | Y8: =N8 -> 0 | Z8: =Y8-U8 -> 0 | AA8: El porcentaje reportado puede ser aporte al avance global; no necesariamente avance interno.
A9: 05483 | B9: Nariño | C9: Oriente | D9: Provincia La Paz | E9: Original | F9: 91 | H9: =IF(G9="",F9,G9) -> 91 | I9: 0 | J9: 0 | K9: 0 | N9: =I9*Resumen!$C$6+J9*Resumen!$C$7+K9*Resumen!$C$8 -> 0 | O9: =H9*N9 -> 0 | P9: =H9-O9 -> 91 | Q9: =IF(L9>0,MIN(1,M9/L9,IF(K9=0,N9,1)),0) -> 0 | R9: =H9*Q9 -> 0 | S9: =IF(N9>0,H9,0) -> 0 | T9: =IF(N9>0,"Con entregas","Sin entregas") -> Sin entregas | U9: =I9*Resumen!$C$6+J9*Resumen!$C$7+K9*Resumen!$C$9 -> 0 | V9: =H9*U9 -> 0 | W9: =IF(COUNTIF(I9:K9,1)>0,1,0) -> 0 | X9: =COUNTIF(I9:K9,1)/3 -> 0 | Y9: =N9 -> 0 | Z9: =Y9-U9 -> 0 | AA9: El porcentaje reportado puede ser aporte al avance global; no necesariamente avance interno.
A10: 05467 | B10: Montebello | C10: Suroeste | D10: Provincia Cartama | E10: Original | F10: 63.7 | H10: =IF(G10="",F10,G10) -> 63.7 | I10: 0 | J10: 0 | K10: 0 | N10: =I10*Resumen!$C$6+J10*Resumen!$C$7+K10*Resumen!$C$8 -> 0 | O10: =H10*N10 -> 0 | P10: =H10-O10 -> 63.7 | Q10: =IF(L10>0,MIN(1,M10/L10,IF(K10=0,N10,1)),0) -> 0 | R10: =H10*Q10 -> 0 | S10: =IF(N10>0,H10,0) -> 0 | T10: =IF(N10>0,"Con entregas","Sin entregas") -> Sin entregas | U10: =I10*Resumen!$C$6+J10*Resumen!$C$7+K10*Resumen!$C$9 -> 0 | V10: =H10*U10 -> 0 | W10: =IF(COUNTIF(I10:K10,1)>0,1,0) -> 0 | X10: =COUNTIF(I10:K10,1)/3 -> 0 | Y10: =N10 -> 0 | Z10: =Y10-U10 -> 0 | AA10: El porcentaje reportado puede ser aporte al avance global; no necesariamente avance interno.
A11: 05628 | B11: Sabanalarga | C11: Occidente | D11: Provincia Occidente | E11: Original | F11: 161.2 | H11: =IF(G11="",F11,G11) -> 161.2 | I11: 0 | J11: 0 | K11: 0 | N11: =I11*Resumen!$C$6+J11*Resumen!$C$7+K11*Resumen!$C$8 -> 0 | O11: =H11*N11 -> 0 | P11: =H11-O11 -> 161.2 | Q11: =IF(L11>0,MIN(1,M11/L11,IF(K11=0,N11,1)),0) -> 0 | R11: =H11*Q11 -> 0 | S11: =IF(N11>0,H11,0) -> 0 | T11: =IF(N11>0,"Con entregas","Sin entregas") -> Sin entregas | U11: =I11*Resumen!$C$6+J11*Resumen!$C$7+K11*Resumen!$C$9 -> 0 | V11: =H11*U11 -> 0 | W11: =IF(COUNTIF(I11:K11,1)>0,1,0) -> 0 | X11: =COUNTIF(I11:K11,1)/3 -> 0 | Y11: =N11 -> 0 | Z11: =Y11-U11 -> 0 | AA11: El porcentaje reportado puede ser aporte al avance global; no necesariamente avance interno.
A12: 05656 | B12: San Jerónimo | C12: Occidente | D12: Provincia Occidente | E12: Original | F12: 331.5 | H12: =IF(G12="",F12,G12) -> 331.5 | I12: 0 | J12: 0 | K12: 0 | N12: =I12*Resumen!$C$6+J12*Resumen!$C$7+K12*Resumen!$C$8 -> 0 | O12: =H12*N12 -> 0 | P12: =H12-O12 -> 331.5 | Q12: =IF(L12>0,MIN(1,M12/L12,IF(K12=0,N12,1)),0) -> 0 | R12: =H12*Q12 -> 0 | S12: =IF(N12>0,H12,0) -> 0 | T12: =IF(N12>0,"Con entregas","Sin entregas") -> Sin entregas | U12: =I12*Resumen!$C$6+J12*Resumen!$C$7+K12*Resumen!$C$9 -> 0 | V12: =H12*U12 -> 0 | W12: =IF(COUNTIF(I12:K12,1)>0,1,0) -> 0 | X12: =COUNTIF(I12:K12,1)/3 -> 0 | Y12: =N12 -> 0 | Z12: =Y12-U12 -> 0 | AA12: El porcentaje reportado puede ser aporte al avance global; no necesariamente avance interno.
A13: 05042 | B13: Santa Fe de Antioquia | C13: Occidente | D13: Provincia Occidente | E13: Original | F13: 297.7 | G13: 371.25 | H13: =IF(G13="",F13,G13) -> 371.25 | I13: 1 | J13: 1 | K13: 1 | L13: 0.0423 | M13: 0.0413 | N13: =I13*Resumen!$C$6+J13*Resumen!$C$7+K13*Resumen!$C$8 -> 0.9 | O13: =H13*N13 -> 334.125 | P13: =H13-O13 -> 37.125 | Q13: =IF(L13>0,MIN(1,M13/L13,IF(K13=0,N13,1)),0) -> 0.97635934 | R13: =H13*Q13 -> 362.4734 | S13: =IF(N13>0,H13,0) -> 371.25 | T13: =IF(N13>0,"Con entregas","Sin entregas") -> Con entregas | U13: =I13*Resumen!$C$6+J13*Resumen!$C$7+K13*Resumen!$C$9 -> 1 | V13: =H13*U13 -> 371.25 | W13: =IF(COUNTIF(I13:K13,1)>0,1,0) -> 1 | X13: =COUNTIF(I13:K13,1)/3 -> 1 | Y13: =N13 -> 0.9 | Z13: =Y13-U13 -> -0.1 | AA13: El porcentaje reportado puede ser aporte al avance global; no necesariamente avance interno.
A14: 05736 | B14: Segovia | C14: Nordeste | D14: Provincia Minero Agroecológica | E14: Original | F14: 374.4 | H14: =IF(G14="",F14,G14) -> 374.4 | I14: 0 | J14: 0 | K14: 0 | N14: =I14*Resumen!$C$6+J14*Resumen!$C$7+K14*Resumen!$C$8 -> 0 | O14: =H14*N14 -> 0 | P14: =H14-O14 -> 374.4 | Q14: =IF(L14>0,MIN(1,M14/L14,IF(K14=0,N14,1)),0) -> 0 | R14: =H14*Q14 -> 0 | S14: =IF(N14>0,H14,0) -> 0 | T14: =IF(N14>0,"Con entregas","Sin entregas") -> Sin entregas | U14: =I14*Resumen!$C$6+J14*Resumen!$C$7+K14*Resumen!$C$9 -> 0 | V14: =H14*U14 -> 0 | W14: =IF(COUNTIF(I14:K14,1)>0,1,0) -> 0 | X14: =COUNTIF(I14:K14,1)/3 -> 0 | Y14: =N14 -> 0 | Z14: =Y14-U14 -> 0 | AA14: El porcentaje reportado puede ser aporte al avance global; no necesariamente avance interno.
A15: 05885 | B15: Yalí | C15: Nordeste | D15: Provincia Mineros | E15: Original | F15: 106.6 | H15: =IF(G15="",F15,G15) -> 106.6 | I15: 0 | J15: 0 | K15: 0 | N15: =I15*Resumen!$C$6+J15*Resumen!$C$7+K15*Resumen!$C$8 -> 0 | O15: =H15*N15 -> 0 | P15: =H15-O15 -> 106.6 | Q15: =IF(L15>0,MIN(1,M15/L15,IF(K15=0,N15,1)),0) -> 0 | R15: =H15*Q15 -> 0 | S15: =IF(N15>0,H15,0) -> 0 | T15: =IF(N15>0,"Con entregas","Sin entregas") -> Sin entregas | U15: =I15*Resumen!$C$6+J15*Resumen!$C$7+K15*Resumen!$C$9 -> 0 | V15: =H15*U15 -> 0 | W15: =IF(COUNTIF(I15:K15,1)>0,1,0) -> 0 | X15: =COUNTIF(I15:K15,1)/3 -> 0 | Y15: =N15 -> 0 | Z15: =Y15-U15 -> 0 | AA15: El porcentaje reportado puede ser aporte al avance global; no necesariamente avance interno.
A16: 05890 | B16: Yolombó | C16: Nordeste | D16: Provincia Mineros | E16: Original | F16: 263.9 | H16: =IF(G16="",F16,G16) -> 263.9 | I16: 0 | J16: 0 | K16: 0 | N16: =I16*Resumen!$C$6+J16*Resumen!$C$7+K16*Resumen!$C$8 -> 0 | O16: =H16*N16 -> 0 | P16: =H16-O16 -> 263.9 | Q16: =IF(L16>0,MIN(1,M16/L16,IF(K16=0,N16,1)),0) -> 0 | R16: =H16*Q16 -> 0 | S16: =IF(N16>0,H16,0) -> 0 | T16: =IF(N16>0,"Con entregas","Sin entregas") -> Sin entregas | U16: =I16*Resumen!$C$6+J16*Resumen!$C$7+K16*Resumen!$C$9 -> 0 | V16: =H16*U16 -> 0 | W16: =IF(COUNTIF(I16:K16,1)>0,1,0) -> 0 | X16: =COUNTIF(I16:K16,1)/3 -> 0 | Y16: =N16 -> 0 | Z16: =Y16-U16 -> 0 | AA16: El porcentaje reportado puede ser aporte al avance global; no necesariamente avance interno.
A17: 05004 | B17: Abriaquí | C17: Occidente | D17: Sin provincia asignada | E17: Original | F17: 15.6 | H17: =IF(G17="",F17,G17) -> 15.6 | I17: 0 | J17: 0 | K17: 0 | N17: =I17*Resumen!$C$6+J17*Resumen!$C$7+K17*Resumen!$C$8 -> 0 | O17: =H17*N17 -> 0 | P17: =H17-O17 -> 15.6 | Q17: =IF(L17>0,MIN(1,M17/L17,IF(K17=0,N17,1)),0) -> 0 | R17: =H17*Q17 -> 0 | S17: =IF(N17>0,H17,0) -> 0 | T17: =IF(N17>0,"Con entregas","Sin entregas") -> Sin entregas | U17: =I17*Resumen!$C$6+J17*Resumen!$C$7+K17*Resumen!$C$9 -> 0 | V17: =H17*U17 -> 0 | W17: =IF(COUNTIF(I17:K17,1)>0,1,0) -> 0 | X17: =COUNTIF(I17:K17,1)/3 -> 0 | Y17: =N17 -> 0 | Z17: =Y17-U17 -> 0 | AA17: El porcentaje reportado puede ser aporte al avance global; no necesariamente avance interno.
A18: 05038 | B18: Angostura | C18: Norte | D18: Sin provincia asignada | E18: Original | F18: 70.2 | G18: 62.56 | H18: =IF(G18="",F18,G18) -> 62.56 | I18: 1 | J18: 1 | K18: 0 | L18: 0.0071 | M18: 0.0057 | N18: =I18*Resumen!$C$6+J18*Resumen!$C$7+K18*Resumen!$C$8 -> 0.9 | O18: =H18*N18 -> 56.304 | P18: =H18-O18 -> 6.256 | Q18: =IF(L18>0,MIN(1,M18/L18,IF(K18=0,N18,1)),0) -> 0.8028169 | R18: =H18*Q18 -> 50.224225 | S18: =IF(N18>0,H18,0) -> 62.56 | T18: =IF(N18>0,"Con entregas","Sin entregas") -> Con entregas | U18: =I18*Resumen!$C$6+J18*Resumen!$C$7+K18*Resumen!$C$9 -> 0.9 | V18: =H18*U18 -> 56.304 | W18: =IF(COUNTIF(I18:K18,1)>0,1,0) -> 1 | X18: =COUNTIF(I18:K18,1)/3 -> 0.66666667 | Y18: =N18 -> 0.9 | Z18: =Y18-U18 -> 0 | AA18: El porcentaje reportado puede ser aporte al avance global; no necesariamente avance interno.
A19: 05059 | B19: Armenia | C19: Occidente | D19: Sin provincia asignada | E19: Original | F19: 22.1 | H19: =IF(G19="",F19,G19) -> 22.1 | I19: 0 | J19: 0 | K19: 0 | N19: =I19*Resumen!$C$6+J19*Resumen!$C$7+K19*Resumen!$C$8 -> 0 | O19: =H19*N19 -> 0 | P19: =H19-O19 -> 22.1 | Q19: =IF(L19>0,MIN(1,M19/L19,IF(K19=0,N19,1)),0) -> 0 | R19: =H19*Q19 -> 0 | S19: =IF(N19>0,H19,0) -> 0 | T19: =IF(N19>0,"Con entregas","Sin entregas") -> Sin entregas | U19: =I19*Resumen!$C$6+J19*Resumen!$C$7+K19*Resumen!$C$9 -> 0 | V19: =H19*U19 -> 0 | W19: =IF(COUNTIF(I19:K19,1)>0,1,0) -> 0 | X19: =COUNTIF(I19:K19,1)/3 -> 0 | Y19: =N19 -> 0 | Z19: =Y19-U19 -> 0 | AA19: El porcentaje reportado puede ser aporte al avance global; no necesariamente avance interno.
A20: 05086 | B20: Belmira | C20: Norte | D20: Sin provincia asignada | E20: Original | F20: 76.7 | G20: 96.5 | H20: =IF(G20="",F20,G20) -> 96.5 | I20: 1 | J20: 1 | K20: 0 | L20: 0.011 | M20: 0.0099 | N20: =I20*Resumen!$C$6+J20*Resumen!$C$7+K20*Resumen!$C$8 -> 0.9 | O20: =H20*N20 -> 86.85 | P20: =H20-O20 -> 9.65 | Q20: =IF(L20>0,MIN(1,M20/L20,IF(K20=0,N20,1)),0) -> 0.9 | R20: =H20*Q20 -> 86.85 | S20: =IF(N20>0,H20,0) -> 96.5 | T20: =IF(N20>0,"Con entregas","Sin entregas") -> Con entregas | U20: =I20*Resumen!$C$6+J20*Resumen!$C$7+K20*Resumen!$C$9 -> 0.9 | V20: =H20*U20 -> 86.85 | W20: =IF(COUNTIF(I20:K20,1)>0,1,0) -> 1 | X20: =COUNTIF(I20:K20,1)/3 -> 0.66666667 | Y20: =N20 -> 0.9 | Z20: =Y20-U20 -> 0 | AA20: El porcentaje reportado puede ser aporte al avance global; no necesariamente avance interno.
A21: 05113 | B21: Buriticá | C21: Occidente | D21: Sin provincia asignada | E21: Original | F21: 13 | H21: =IF(G21="",F21,G21) -> 13 | I21: 0 | J21: 0 | K21: 0 | N21: =I21*Resumen!$C$6+J21*Resumen!$C$7+K21*Resumen!$C$8 -> 0 | O21: =H21*N21 -> 0 | P21: =H21-O21 -> 13 | Q21: =IF(L21>0,MIN(1,M21/L21,IF(K21=0,N21,1)),0) -> 0 | R21: =H21*Q21 -> 0 | S21: =IF(N21>0,H21,0) -> 0 | T21: =IF(N21>0,"Con entregas","Sin entregas") -> Sin entregas | U21: =I21*Resumen!$C$6+J21*Resumen!$C$7+K21*Resumen!$C$9 -> 0 | V21: =H21*U21 -> 0 | W21: =IF(COUNTIF(I21:K21,1)>0,1,0) -> 0 | X21: =COUNTIF(I21:K21,1)/3 -> 0 | Y21: =N21 -> 0 | Z21: =Y21-U21 -> 0 | AA21: El porcentaje reportado puede ser aporte al avance global; no necesariamente avance interno.
A22: 05134 | B22: Campamento | C22: Norte | D22: Sin provincia asignada | E22: Original | F22: 57.2 | H22: =IF(G22="",F22,G22) -> 57.2 | I22: 0 | J22: 0 | K22: 0 | N22: =I22*Resumen!$C$6+J22*Resumen!$C$7+K22*Resumen!$C$8 -> 0 | O22: =H22*N22 -> 0 | P22: =H22-O22 -> 57.2 | Q22: =IF(L22>0,MIN(1,M22/L22,IF(K22=0,N22,1)),0) -> 0 | R22: =H22*Q22 -> 0 | S22: =IF(N22>0,H22,0) -> 0 | T22: =IF(N22>0,"Con entregas","Sin entregas") -> Sin entregas | U22: =I22*Resumen!$C$6+J22*Resumen!$C$7+K22*Resumen!$C$9 -> 0 | V22: =H22*U22 -> 0 | W22: =IF(COUNTIF(I22:K22,1)>0,1,0) -> 0 | X22: =COUNTIF(I22:K22,1)/3 -> 0 | Y22: =N22 -> 0 | Z22: =Y22-U22 -> 0 | AA22: El porcentaje reportado puede ser aporte al avance global; no necesariamente avance interno.
A23: 05142 | B23: Caracolí | C23: Magdalena Medio | D23: Sin provincia asignada | E23: Original | F23: 32.5 | H23: =IF(G23="",F23,G23) -> 32.5 | I23: 0 | J23: 0 | K23: 0 | N23: =I23*Resumen!$C$6+J23*Resumen!$C$7+K23*Resumen!$C$8 -> 0 | O23: =H23*N23 -> 0 | P23: =H23-O23 -> 32.5 | Q23: =IF(L23>0,MIN(1,M23/L23,IF(K23=0,N23,1)),0) -> 0 | R23: =H23*Q23 -> 0 | S23: =IF(N23>0,H23,0) -> 0 | T23: =IF(N23>0,"Con entregas","Sin entregas") -> Sin entregas | U23: =I23*Resumen!$C$6+J23*Resumen!$C$7+K23*Resumen!$C$9 -> 0 | V23: =H23*U23 -> 0 | W23: =IF(COUNTIF(I23:K23,1)>0,1,0) -> 0 | X23: =COUNTIF(I23:K23,1)/3 -> 0 | Y23: =N23 -> 0 | Z23: =Y23-U23 -> 0 | AA23: El porcentaje reportado puede ser aporte al avance global; no necesariamente avance interno.
A24: 05138 | B24: Cañasgordas | C24: Occidente | D24: Sin provincia asignada | E24: Original | F24: 107.9 | H24: =IF(G24="",F24,G24) -> 107.9 | I24: 0 | J24: 0 | K24: 0 | N24: =I24*Resumen!$C$6+J24*Resumen!$C$7+K24*Resumen!$C$8 -> 0 | O24: =H24*N24 -> 0 | P24: =H24-O24 -> 107.9 | Q24: =IF(L24>0,MIN(1,M24/L24,IF(K24=0,N24,1)),0) -> 0 | R24: =H24*Q24 -> 0 | S24: =IF(N24>0,H24,0) -> 0 | T24: =IF(N24>0,"Con entregas","Sin entregas") -> Sin entregas | U24: =I24*Resumen!$C$6+J24*Resumen!$C$7+K24*Resumen!$C$9 -> 0 | V24: =H24*U24 -> 0 | W24: =IF(COUNTIF(I24:K24,1)>0,1,0) -> 0 | X24: =COUNTIF(I24:K24,1)/3 -> 0 | Y24: =N24 -> 0 | Z24: =Y24-U24 -> 0 | AA24: El porcentaje reportado puede ser aporte al avance global; no necesariamente avance interno.
A25: 05190 | B25: Cisneros | C25: Nordeste | D25: Sin provincia asignada | E25: Original | F25: 98.8 | G25: 194.38 | H25: =IF(G25="",F25,G25) -> 194.38 | I25: 1 | J25: 1 | K25: 0 | L25: 0.0221 | M25: 0.0199 | N25: =I25*Resumen!$C$6+J25*Resumen!$C$7+K25*Resumen!$C$8 -> 0.9 | O25: =H25*N25 -> 174.942 | P25: =H25-O25 -> 19.438 | Q25: =IF(L25>0,MIN(1,M25/L25,IF(K25=0,N25,1)),0) -> 0.9 | R25: =H25*Q25 -> 174.942 | S25: =IF(N25>0,H25,0) -> 194.38 | T25: =IF(N25>0,"Con entregas","Sin entregas") -> Con entregas | U25: =I25*Resumen!$C$6+J25*Resumen!$C$7+K25*Resumen!$C$9 -> 0.9 | V25: =H25*U25 -> 174.942 | W25: =IF(COUNTIF(I25:K25,1)>0,1,0) -> 1 | X25: =COUNTIF(I25:K25,1)/3 -> 0.66666667 | Y25: =N25 -> 0.9 | Z25: =Y25-U25 -> 0 | AA25: El porcentaje reportado puede ser aporte al avance global; no necesariamente avance interno.
A26: 05120 | B26: Cáceres | C26: Bajo Cauca | D26: Sin provincia asignada | E26: Original | F26: 212.11 | H26: =IF(G26="",F26,G26) -> 212.11 | I26: 0 | J26: 0 | K26: 0 | N26: =I26*Resumen!$C$6+J26*Resumen!$C$7+K26*Resumen!$C$8 -> 0 | O26: =H26*N26 -> 0 | P26: =H26-O26 -> 212.11 | Q26: =IF(L26>0,MIN(1,M26/L26,IF(K26=0,N26,1)),0) -> 0 | R26: =H26*Q26 -> 0 | S26: =IF(N26>0,H26,0) -> 0 | T26: =IF(N26>0,"Con entregas","Sin entregas") -> Sin entregas | U26: =I26*Resumen!$C$6+J26*Resumen!$C$7+K26*Resumen!$C$9 -> 0 | V26: =H26*U26 -> 0 | W26: =IF(COUNTIF(I26:K26,1)>0,1,0) -> 0 | X26: =COUNTIF(I26:K26,1)/3 -> 0 | Y26: =N26 -> 0 | Z26: =Y26-U26 -> 0 | AA26: El porcentaje reportado puede ser aporte al avance global; no necesariamente avance interno.
A27: 05234 | B27: Dabeiba | C27: Occidente | D27: Sin provincia asignada | E27: Original | F27: 158.6 | H27: =IF(G27="",F27,G27) -> 158.6 | I27: 0 | J27: 0 | K27: 0 | N27: =I27*Resumen!$C$6+J27*Resumen!$C$7+K27*Resumen!$C$8 -> 0 | O27: =H27*N27 -> 0 | P27: =H27-O27 -> 158.6 | Q27: =IF(L27>0,MIN(1,M27/L27,IF(K27=0,N27,1)),0) -> 0 | R27: =H27*Q27 -> 0 | S27: =IF(N27>0,H27,0) -> 0 | T27: =IF(N27>0,"Con entregas","Sin entregas") -> Sin entregas | U27: =I27*Resumen!$C$6+J27*Resumen!$C$7+K27*Resumen!$C$9 -> 0 | V27: =H27*U27 -> 0 | W27: =IF(COUNTIF(I27:K27,1)>0,1,0) -> 0 | X27: =COUNTIF(I27:K27,1)/3 -> 0 | Y27: =N27 -> 0 | Z27: =Y27-U27 -> 0 | AA27: El porcentaje reportado puede ser aporte al avance global; no necesariamente avance interno.
A28: 05240 | B28: Ebéjico | C28: Occidente | D28: Sin provincia asignada | E28: Original | F28: 41.6 | H28: =IF(G28="",F28,G28) -> 41.6 | I28: 0 | J28: 0 | K28: 0 | N28: =I28*Resumen!$C$6+J28*Resumen!$C$7+K28*Resumen!$C$8 -> 0 | O28: =H28*N28 -> 0 | P28: =H28-O28 -> 41.6 | Q28: =IF(L28>0,MIN(1,M28/L28,IF(K28=0,N28,1)),0) -> 0 | R28: =H28*Q28 -> 0 | S28: =IF(N28>0,H28,0) -> 0 | T28: =IF(N28>0,"Con entregas","Sin entregas") -> Sin entregas | U28: =I28*Resumen!$C$6+J28*Resumen!$C$7+K28*Resumen!$C$9 -> 0 | V28: =H28*U28 -> 0 | W28: =IF(COUNTIF(I28:K28,1)>0,1,0) -> 0 | X28: =COUNTIF(I28:K28,1)/3 -> 0 | Y28: =N28 -> 0 | Z28: =Y28-U28 -> 0 | AA28: El porcentaje reportado puede ser aporte al avance global; no necesariamente avance interno.
A29: 05250 | B29: El Bagre | C29: Bajo Cauca | D29: Sin provincia asignada | E29: Original | F29: 1391 | G29: 1092.62 | H29: =IF(G29="",F29,G29) -> 1092.62 | I29: 1 | J29: 0 | K29: 0 | L29: 0.1244 | M29: 0.056 | N29: =I29*Resumen!$C$6+J29*Resumen!$C$7+K29*Resumen!$C$8 -> 0.45 | O29: =H29*N29 -> 491.679 | P29: =H29-O29 -> 600.941 | Q29: =IF(L29>0,MIN(1,M29/L29,IF(K29=0,N29,1)),0) -> 0.45 | R29: =H29*Q29 -> 491.679 | S29: =IF(N29>0,H29,0) -> 1092.62 | T29: =IF(N29>0,"Con entregas","Sin entregas") -> Con entregas | U29: =I29*Resumen!$C$6+J29*Resumen!$C$7+K29*Resumen!$C$9 -> 0.45 | V29: =H29*U29 -> 491.679 | W29: =IF(COUNTIF(I29:K29,1)>0,1,0) -> 1 | X29: =COUNTIF(I29:K29,1)/3 -> 0.33333333 | Y29: =N29 -> 0.45 | Z29: =Y29-U29 -> 0 | AA29: El porcentaje reportado puede ser aporte al avance global; no necesariamente avance interno.
A30: 05264 | B30: Entrerríos | C30: Norte | D30: Sin provincia asignada | E30: Original | F30: 119.6 | G30: 163.82 | H30: =IF(G30="",F30,G30) -> 163.82 | I30: 1 | J30: 1 | K30: 0 | L30: 0.0187 | M30: 0.0168 | N30: =I30*Resumen!$C$6+J30*Resumen!$C$7+K30*Resumen!$C$8 -> 0.9 | O30: =H30*N30 -> 147.438 | P30: =H30-O30 -> 16.382 | Q30: =IF(L30>0,MIN(1,M30/L30,IF(K30=0,N30,1)),0) -> 0.89839572 | R30: =H30*Q30 -> 147.17519 | S30: =IF(N30>0,H30,0) -> 163.82 | T30: =IF(N30>0,"Con entregas","Sin entregas") -> Con entregas | U30: =I30*Resumen!$C$6+J30*Resumen!$C$7+K30*Resumen!$C$9 -> 0.9 | V30: =H30*U30 -> 147.438 | W30: =IF(COUNTIF(I30:K30,1)>0,1,0) -> 1 | X30: =COUNTIF(I30:K30,1)/3 -> 0.66666667 | Y30: =N30 -> 0.9 | Z30: =Y30-U30 -> 0 | AA30: El porcentaje reportado puede ser aporte al avance global; no necesariamente avance interno.
A31: 05284 | B31: Frontino | C31: Occidente | D31: Sin provincia asignada | E31: Original | F31: 349.7 | H31: =IF(G31="",F31,G31) -> 349.7 | I31: 0 | J31: 0 | K31: 0 | N31: =I31*Resumen!$C$6+J31*Resumen!$C$7+K31*Resumen!$C$8 -> 0 | O31: =H31*N31 -> 0 | P31: =H31-O31 -> 349.7 | Q31: =IF(L31>0,MIN(1,M31/L31,IF(K31=0,N31,1)),0) -> 0 | R31: =H31*Q31 -> 0 | S31: =IF(N31>0,H31,0) -> 0 | T31: =IF(N31>0,"Con entregas","Sin entregas") -> Sin entregas | U31: =I31*Resumen!$C$6+J31*Resumen!$C$7+K31*Resumen!$C$9 -> 0 | V31: =H31*U31 -> 0 | W31: =IF(COUNTIF(I31:K31,1)>0,1,0) -> 0 | X31: =COUNTIF(I31:K31,1)/3 -> 0 | Y31: =N31 -> 0 | Z31: =Y31-U31 -> 0 | AA31: El porcentaje reportado puede ser aporte al avance global; no necesariamente avance interno.
A32: 05306 | B32: Giraldo | C32: Occidente | D32: Sin provincia asignada | E32: Original | F32: 74.1 | G32: 62.22 | H32: =IF(G32="",F32,G32) -> 62.22 | I32: 1 | J32: 0 | K32: 0 | L32: 0.0071 | M32: 0.0027 | N32: =I32*Resumen!$C$6+J32*Resumen!$C$7+K32*Resumen!$C$8 -> 0.45 | O32: =H32*N32 -> 27.999 | P32: =H32-O32 -> 34.221 | Q32: =IF(L32>0,MIN(1,M32/L32,IF(K32=0,N32,1)),0) -> 0.38028169 | R32: =H32*Q32 -> 23.661127 | S32: =IF(N32>0,H32,0) -> 62.22 | T32: =IF(N32>0,"Con entregas","Sin entregas") -> Con entregas | U32: =I32*Resumen!$C$6+J32*Resumen!$C$7+K32*Resumen!$C$9 -> 0.45 | V32: =H32*U32 -> 27.999 | W32: =IF(COUNTIF(I32:K32,1)>0,1,0) -> 1 | X32: =COUNTIF(I32:K32,1)/3 -> 0.33333333 | Y32: =N32 -> 0.45 | Z32: =Y32-U32 -> 0 | AA32: El porcentaje reportado puede ser aporte al avance global; no necesariamente avance interno.
A33: 05315 | B33: Guadalupe | C33: Norte | D33: Sin provincia asignada | E33: Original | F33: 44.2 | H33: =IF(G33="",F33,G33) -> 44.2 | I33: 0 | J33: 0 | K33: 0 | N33: =I33*Resumen!$C$6+J33*Resumen!$C$7+K33*Resumen!$C$8 -> 0 | O33: =H33*N33 -> 0 | P33: =H33-O33 -> 44.2 | Q33: =IF(L33>0,MIN(1,M33/L33,IF(K33=0,N33,1)),0) -> 0 | R33: =H33*Q33 -> 0 | S33: =IF(N33>0,H33,0) -> 0 | T33: =IF(N33>0,"Con entregas","Sin entregas") -> Sin entregas | U33: =I33*Resumen!$C$6+J33*Resumen!$C$7+K33*Resumen!$C$9 -> 0 | V33: =H33*U33 -> 0 | W33: =IF(COUNTIF(I33:K33,1)>0,1,0) -> 0 | X33: =COUNTIF(I33:K33,1)/3 -> 0 | Y33: =N33 -> 0 | Z33: =Y33-U33 -> 0 | AA33: El porcentaje reportado puede ser aporte al avance global; no necesariamente avance interno.
A34: 05347 | B34: Heliconia | C34: Occidente | D34: Sin provincia asignada | E34: Original | F34: 62.4 | H34: =IF(G34="",F34,G34) -> 62.4 | I34: 0 | J34: 0 | K34: 0 | N34: =I34*Resumen!$C$6+J34*Resumen!$C$7+K34*Resumen!$C$8 -> 0 | O34: =H34*N34 -> 0 | P34: =H34-O34 -> 62.4 | Q34: =IF(L34>0,MIN(1,M34/L34,IF(K34=0,N34,1)),0) -> 0 | R34: =H34*Q34 -> 0 | S34: =IF(N34>0,H34,0) -> 0 | T34: =IF(N34>0,"Con entregas","Sin entregas") -> Sin entregas | U34: =I34*Resumen!$C$6+J34*Resumen!$C$7+K34*Resumen!$C$9 -> 0 | V34: =H34*U34 -> 0 | W34: =IF(COUNTIF(I34:K34,1)>0,1,0) -> 0 | X34: =COUNTIF(I34:K34,1)/3 -> 0 | Y34: =N34 -> 0 | Z34: =Y34-U34 -> 0 | AA34: El porcentaje reportado puede ser aporte al avance global; no necesariamente avance interno.
